<mujoco model="ur5e_hande">
  <compiler angle="radian" autolimits="true"/>

  <option impratio="10" integrator="implicitfast" cone="elliptic"/>

  <default>
    <default class="/"/>
    <default class="ur5e/">
      <default class="ur5e/ur5e">
        <material shininess="0.25"/>
        <joint range="-6.28319 6.28319" armature="0.1"/>
        <site size="0.001 0.005 0.005" group="4" rgba="0.5 0.5 0.5 0.3"/>
        <general ctrlrange="-6.2831 6.2831" forcerange="-150 150" biastype="affine" gainprm="2000" biasprm="0 -2000 -400"/>
        <default class="ur5e/size3">
          <default class="ur5e/size3_limited">
            <joint range="-3.1415 3.1415"/>
            <general ctrlrange="-3.1415 3.1415"/>
          </default>
        </default>
        <default class="ur5e/size1">
          <general forcerange="-28 28" gainprm="500" biasprm="0 -500 -100"/>
        </default>
        <default class="ur5e/visual">
          <geom type="mesh" contype="0" conaffinity="0" group="2"/>
        </default>
        <default class="ur5e/collision">
          <geom type="capsule" group="3"/>
          <default class="ur5e/eef_collision">
            <geom type="cylinder"/>
          </default>
        </default>
      </default>
    </default>
    <default class="ur5e/robotiq_hande/">
      <default class="ur5e/robotiq_hande/hande">
        <default class="ur5e/robotiq_hande/hande_right_finger">
          <joint type="slide" range="0 0.025"/>
        </default>
        <default class="ur5e/robotiq_hande/hande_left_finger">
          <joint type="slide" range="0 0.025"/>
        </default>
      </default>
    </default>
  </default>

  <asset>
    <texture type="2d" name="//unnamed_texture_0" builtin="checker" rgb1="0.2 0.3 0.4" rgb2="0.3 0.4 0.5" width="300" height="300"/>
    <material name="grid_1" class="/" texture="//unnamed_texture_0" texrepeat="5 5" reflectance="0.2"/>
    <material name="ur5e/black" class="ur5e/ur5e" rgba="0.033 0.033 0.033 1"/>
    <material name="ur5e/jointgray" class="ur5e/ur5e" rgba="0.278 0.278 0.278 1"/>
    <material name="ur5e/linkgray" class="ur5e/ur5e" rgba="0.82 0.82 0.82 1"/>
    <material name="ur5e/urblue" class="ur5e/ur5e" rgba="0.49 0.678 0.8 1"/>
    <mesh name="ur5e/base_0" class="ur5e/" file="ur5e/assets/base_0.obj"/>
    <mesh name="ur5e/base_1" class="ur5e/" file="ur5e/assets/base_1.obj"/>
    <mesh name="ur5e/shoulder_0" class="ur5e/" file="ur5e/assets/shoulder_0.obj"/>
    <mesh name="ur5e/shoulder_1" class="ur5e/" file="ur5e/assets/shoulder_1.obj"/>
    <mesh name="ur5e/shoulder_2" class="ur5e/" file="ur5e/assets/shoulder_2.obj"/>
    <mesh name="ur5e/upperarm_0" class="ur5e/" file="ur5e/assets/upperarm_0.obj"/>
    <mesh name="ur5e/upperarm_1" class="ur5e/" file="ur5e/assets/upperarm_1.obj"/>
    <mesh name="ur5e/upperarm_2" class="ur5e/" file="ur5e/assets/upperarm_2.obj"/>
    <mesh name="ur5e/upperarm_3" class="ur5e/" file="ur5e/assets/upperarm_3.obj"/>
    <mesh name="ur5e/forearm_0" class="ur5e/" file="ur5e/assets/forearm_0.obj"/>
    <mesh name="ur5e/forearm_1" class="ur5e/" file="ur5e/assets/forearm_1.obj"/>
    <mesh name="ur5e/forearm_2" class="ur5e/" file="ur5e/assets/forearm_2.obj"/>
    <mesh name="ur5e/forearm_3" class="ur5e/" file="ur5e/assets/forearm_3.obj"/>
    <mesh name="ur5e/wrist1_0" class="ur5e/" file="ur5e/assets/wrist1_0.obj"/>
    <mesh name="ur5e/wrist1_1" class="ur5e/" file="ur5e/assets/wrist1_1.obj"/>
    <mesh name="ur5e/wrist1_2" class="ur5e/" file="ur5e/assets/wrist1_2.obj"/>
    <mesh name="ur5e/wrist2_0" class="ur5e/" file="ur5e/assets/wrist2_0.obj"/>
    <mesh name="ur5e/wrist2_1" class="ur5e/" file="ur5e/assets/wrist2_1.obj"/>
    <mesh name="ur5e/wrist2_2" class="ur5e/" file="ur5e/assets/wrist2_2.obj"/>
    <mesh name="ur5e/wrist3" class="ur5e/" file="ur5e/assets/wrist3.obj"/>
    <mesh name="ur5e/robotiq_hande/hande" class="ur5e/robotiq_hande/" file="hande/assets/hande.stl"/>
    <mesh name="ur5e/robotiq_hande/coupler" class="ur5e/robotiq_hande/" file="hande/assets/coupler.stl"/>
    <mesh name="ur5e/robotiq_hande/right_finger" class="ur5e/robotiq_hande/" file="hande/assets/finger_1.stl"/>
    <mesh name="ur5e/robotiq_hande/left_finger" class="ur5e/robotiq_hande/" file="hande/assets/finger_2.stl"/>
  </asset>


  <worldbody>
    <geom name="//unnamed_geom_0" class="/" size="2 2 0.1" type="plane" material="grid"/>
    <light name="//unnamed_light_0" class="/" pos="-2 -1 3" dir="0.666667 0.333333 -0.666667"/>
    <light name="//unnamed_light_1" class="/" pos="2 -1 3" dir="-0.666667 0.333333 -0.666667"/>
    <body name="mocap" mocap="true">
      <geom name="//unnamed_geom_1" class="/" size="0.015 0.015 0.015" type="box" contype="0" conaffinity="0" rgba="1 0 0 0.2"/>
    </body>
    <body name="ur5e/" quat="0.707107 0 0 -0.707107">
      <light name="ur5e/spotlight" class="ur5e/" target="ur5e/wrist_2_link" pos="0 -1 2" dir="0 0 -1" mode="targetbodycom"/>
      <body name="ur5e/base" childclass="ur5e/ur5e" quat="0.707107 0 0 0.707107">
        <inertial pos="0 0 0" mass="4" diaginertia="0.00443333 0.00443333 0.0072"/>
        <geom name="ur5e//unnamed_geom_0" class="ur5e/visual" material="ur5e/black" mesh="ur5e/base_0"/>
        <geom name="ur5e//unnamed_geom_1" class="ur5e/visual" material="ur5e/jointgray" mesh="ur5e/base_1"/>
        <body name="ur5e/shoulder_link" pos="0 0 0.163">
          <inertial pos="0 0 0" mass="3.7" diaginertia="0.0102675 0.0102675 0.00666"/>
          <joint name="ur5e/shoulder_pan_joint" class="ur5e/size3" pos="0 0 0" axis="0 0 1"/>
          <site name="shoulder_pan_joint"/>
          <geom name="ur5e//unnamed_geom_2" class="ur5e/visual" material="ur5e/urblue" mesh="ur5e/shoulder_0"/>
          <geom name="ur5e//unnamed_geom_3" class="ur5e/visual" material="ur5e/black" mesh="ur5e/shoulder_1"/>
          <geom name="ur5e//unnamed_geom_4" class="ur5e/visual" material="ur5e/jointgray" mesh="ur5e/shoulder_2"/>
          <geom name="ur5e//unnamed_geom_5" class="ur5e/collision" size="0.06 0.06" pos="0 0 -0.04"/>
          <body name="ur5e/upper_arm_link" pos="0 0.138 0" quat="0.707107 0 0.707107 0">
            <inertial pos="0 0 0.2125" mass="8.393" diaginertia="0.133886 0.133886 0.0151074"/>
            <joint name="ur5e/shoulder_lift_joint" class="ur5e/size3" pos="0 0 0" axis="0 1 0"/>
            <site name="shoulder_lift_joint"/>
            <geom name="ur5e//unnamed_geom_6" class="ur5e/visual" material="ur5e/linkgray" mesh="ur5e/upperarm_0"/>
            <geom name="ur5e//unnamed_geom_7" class="ur5e/visual" material="ur5e/black" mesh="ur5e/upperarm_1"/>
            <geom name="ur5e//unnamed_geom_8" class="ur5e/visual" material="ur5e/jointgray" mesh="ur5e/upperarm_2"/>
            <geom name="ur5e//unnamed_geom_9" class="ur5e/visual" material="ur5e/urblue" mesh="ur5e/upperarm_3"/>
            <geom name="ur5e//unnamed_geom_10" class="ur5e/collision" size="0.06 0.06" pos="0 -0.04 0" quat="0.707107 0.707107 0 0"/>
            <geom name="ur5e//unnamed_geom_11" class="ur5e/collision" size="0.05 0.2" pos="0 0 0.2"/>
            <body name="ur5e/forearm_link" pos="0 -0.131 0.425">
              <inertial pos="0 0 0.196" mass="2.275" diaginertia="0.0311796 0.0311796 0.004095"/>
              <joint name="ur5e/elbow_joint" class="ur5e/size3_limited" pos="0 0 0" axis="0 1 0"/>
              <site name="elbow_joint"/>
              <geom name="ur5e//unnamed_geom_12" class="ur5e/visual" material="ur5e/urblue" mesh="ur5e/forearm_0"/>
              <geom name="ur5e//unnamed_geom_13" class="ur5e/visual" material="ur5e/linkgray" mesh="ur5e/forearm_1"/>
              <geom name="ur5e//unnamed_geom_14" class="ur5e/visual" material="ur5e/black" mesh="ur5e/forearm_2"/>
              <geom name="ur5e//unnamed_geom_15" class="ur5e/visual" material="ur5e/jointgray" mesh="ur5e/forearm_3"/>
              <geom name="ur5e//unnamed_geom_16" class="ur5e/collision" size="0.055 0.06" pos="0 0.08 0" quat="0.707107 0.707107 0 0"/>
              <geom name="ur5e//unnamed_geom_17" class="ur5e/collision" size="0.038 0.19" pos="0 0 0.2"/>
              <body name="ur5e/wrist_1_link" pos="0 0 0.392" quat="0.707107 0 0.707107 0">
                <inertial pos="0 0.127 0" mass="1.219" diaginertia="0.0025599 0.0025599 0.0021942"/>
                <joint name="ur5e/wrist_1_joint" class="ur5e/size1" pos="0 0 0" axis="0 1 0"/>
                <site name="wrist_1_joint"/>
                <geom name="ur5e//unnamed_geom_18" class="ur5e/visual" material="ur5e/black" mesh="ur5e/wrist1_0"/>
                <geom name="ur5e//unnamed_geom_19" class="ur5e/visual" material="ur5e/urblue" mesh="ur5e/wrist1_1"/>
                <geom name="ur5e//unnamed_geom_20" class="ur5e/visual" material="ur5e/jointgray" mesh="ur5e/wrist1_2"/>
                <geom name="ur5e//unnamed_geom_21" class="ur5e/collision" size="0.04 0.07" pos="0 0.05 0" quat="0.707107 0.707107 0 0"/>
                <body name="ur5e/wrist_2_link" pos="0 0.127 0">
                  <inertial pos="0 0 0.1" mass="1.219" diaginertia="0.0025599 0.0025599 0.0021942"/>
                  <joint name="ur5e/wrist_2_joint" class="ur5e/size1" pos="0 0 0" axis="0 0 1"/>
                  <site name="wrist_2_joint"/>
                  <geom name="ur5e//unnamed_geom_22" class="ur5e/visual" material="ur5e/black" mesh="ur5e/wrist2_0"/>
                  <geom name="ur5e//unnamed_geom_23" class="ur5e/visual" material="ur5e/urblue" mesh="ur5e/wrist2_1"/>
                  <geom name="ur5e//unnamed_geom_24" class="ur5e/visual" material="ur5e/jointgray" mesh="ur5e/wrist2_2"/>
                  <geom name="ur5e//unnamed_geom_25" class="ur5e/collision" size="0.04 0.06" pos="0 0 0.04"/>
                  <geom name="ur5e//unnamed_geom_26" class="ur5e/collision" size="0.04 0.04" pos="0 0.02 0.1" quat="0.707107 0.707107 0 0"/>
                  <body name="ur5e/wrist_3_link" pos="0 0 0.1">
                    <inertial pos="0 0.0771683 0" quat="0.707107 0 0 0.707107" mass="0.1889" diaginertia="0.000132134 9.90863e-05 9.90863e-05"/>
                    <joint name="ur5e/wrist_3_joint" class="ur5e/size1" pos="0 0 0" axis="0 1 0"/>
                    <site name="wrist_3_joint"/>
                    <geom name="ur5e//unnamed_geom_27" class="ur5e/visual" material="ur5e/linkgray" mesh="ur5e/wrist3"/>
                    <geom name="ur5e//unnamed_geom_28" class="ur5e/eef_collision" size="0.04 0.02" pos="0 0.08 0" quat="0.707107 0.707107 0 0"/>
                    <body name="ur5e/tool0_link" pos="0 0.1 0" quat="-0.707107 0.707107 0 0">
                      <camera name="handcam_depth" pos="-0.05 0 0" fovy="62" quat="0 1 -1 0"/>
                      <camera name="handcam_rgb" pos="-0.05 0.015 0" fovy="42.5" quat="0 1 -1 0"/>
                      <site name="ur5e/attachment_site" quat="0 0 0 1"/>
                      <site name="ur5e/eef_site" pos="0 0 0.05" quat="0 0.707107 -0.707107 0"/>
                      <body name="ur5e/robotiq_hande/" quat="0 0 0 1">
                        <light name="ur5e/robotiq_hande//unnamed_light_0" class="ur5e/robotiq_hande/" pos="0 0 1.5" dir="0 0 -1" directional="true"/>
                        <body name="ur5e/robotiq_hande/hande">
                          <geom name="ur5e/robotiq_hande/hande_coupler" class="ur5e/robotiq_hande/" type="mesh" conaffinity="0" group="1" rgba="0.1 0.1 0.1 1" mesh="ur5e/robotiq_hande/coupler"/>
                          <geom name="ur5e/robotiq_hande/hande_base" class="ur5e/robotiq_hande/" type="mesh" conaffinity="0" group="1" rgba="0.1 0.1 0.1 1" mesh="ur5e/robotiq_hande/hande"/>
                          <site name="pinch" class="ur5e/robotiq_hande/" pos="0 0 0.135" size="0.001" rgba="0 0 0 0.1"/>
                          <body name="ur5e/robotiq_hande/hande_left_finger" pos="0 0 0.099">
                            <inertial pos="0.02262 -0.00759 0.00738" quat="0.871952 0.0369732 -0.211073 0.440205" mass="0.03804" diaginertia="1.22763e-05 1.22763e-05 1.22763e-05"/>
                            <joint name="ur5e/robotiq_hande/hande_left_finger_joint" class="ur5e/robotiq_hande/hande_left_finger" pos="0 0 0" axis="1 0 0"/>
                            <geom name="ur5e/robotiq_hande//unnamed_geom_2" class="ur5e/robotiq_hande/" type="mesh" contype="0" conaffinity="0" group="1" rgba="0.4 0.4 0.4 1" mesh="ur5e/robotiq_hande/left_finger"/>
                          </body>
                          <body name="ur5e/robotiq_hande/hande_right_finger" pos="0 0 0.099">
                            <inertial pos="-0.02262 0.00759 0.00738" quat="0.871952 -0.0369732 0.211073 0.440205" mass="0.03804" diaginertia="1.22763e-05 1.22763e-05 1.22763e-05"/>
                            <joint name="ur5e/robotiq_hande/hande_right_finger_joint" class="ur5e/robotiq_hande/hande_right_finger" pos="0 0 0" axis="-1 0 0"/>
                            <geom name="ur5e/robotiq_hande//unnamed_geom_3" class="ur5e/robotiq_hande/" type="mesh" contype="0" conaffinity="0" group="1" rgba="0.4 0.4 0.4 1" mesh="ur5e/robotiq_hande/right_finger"/>
                          </body>
                        </body>
                      </body>
                    </body>
                  </body>
                </body>
              </body>
            </body>
          </body>
        </body>
      </body>
    </body>
  </worldbody>

  <contact>
    <exclude name="ur5e/robotiq_hande//unnamed_contact_0" body1="ur5e/robotiq_hande/hande" body2="ur5e/robotiq_hande/hande_left_finger"/>
    <exclude name="ur5e/robotiq_hande//unnamed_contact_1" body1="ur5e/robotiq_hande/hande" body2="ur5e/robotiq_hande/hande_right_finger"/>
  </contact>

  <equality>
    <joint name="ur5e/robotiq_hande//unnamed_equality_0" class="ur5e/robotiq_hande/" joint1="ur5e/robotiq_hande/hande_left_finger_joint" joint2="ur5e/robotiq_hande/hande_right_finger_joint" polycoef="0 1 0 0 0"/>
  </equality>

  <tendon>
    <fixed name="ur5e/robotiq_hande/split" class="ur5e/robotiq_hande/">
      <joint joint="ur5e/robotiq_hande/hande_left_finger_joint" coef="0.5"/>
      <joint joint="ur5e/robotiq_hande/hande_right_finger_joint" coef="0.5"/>
    </fixed>
  </tendon>

  <actuator>
    <general class="ur5e/size3" name="ur5e/shoulder_pan" joint="ur5e/shoulder_pan_joint"/>
    <general class="ur5e/size3" name="ur5e/shoulder_lift" joint="ur5e/shoulder_lift_joint"/>
    <general class="ur5e/size3_limited" name="ur5e/elbow" joint="ur5e/elbow_joint"/>
    <general class="ur5e/size1" name="ur5e/wrist_1" joint="ur5e/wrist_1_joint"/>
    <general class="ur5e/size1" name="ur5e/wrist_2" joint="ur5e/wrist_2_joint"/>
    <general class="ur5e/size1" name="ur5e/wrist_3" joint="ur5e/wrist_3_joint"/>
    <general class="ur5e/robotiq_hande/hande" name="ur5e/robotiq_hande/hande_fingers_actuator" tendon="ur5e/robotiq_hande/split" ctrlrange="0 255" forcerange="-200 200" gaintype="affine" biastype="affine" gainprm="0.00980392" biasprm="0 -100 -10"/>
  </actuator>

  <sensor>
  <!-- Joint positions for UR5e -->
  <jointpos name="ur5e/joint1_pos" joint="ur5e/shoulder_pan_joint"/>
  <jointpos name="ur5e/joint2_pos" joint="ur5e/shoulder_lift_joint"/>
  <jointpos name="ur5e/joint3_pos" joint="ur5e/elbow_joint"/>
  <jointpos name="ur5e/joint4_pos" joint="ur5e/wrist_1_joint"/>
  <jointpos name="ur5e/joint5_pos" joint="ur5e/wrist_2_joint"/>
  <jointpos name="ur5e/joint6_pos" joint="ur5e/wrist_3_joint"/>

  <!-- Joint velocities for UR5e -->
  <jointvel name="ur5e/joint1_vel" joint="ur5e/shoulder_pan_joint"/>
  <jointvel name="ur5e/joint2_vel" joint="ur5e/shoulder_lift_joint"/>
  <jointvel name="ur5e/joint3_vel" joint="ur5e/elbow_joint"/>
  <jointvel name="ur5e/joint4_vel" joint="ur5e/wrist_1_joint"/>
  <jointvel name="ur5e/joint5_vel" joint="ur5e/wrist_2_joint"/>
  <jointvel name="ur5e/joint6_vel" joint="ur5e/wrist_3_joint"/>

  <!-- Torque sensors for UR5e joints -->
  <torque name="ur5e/joint1_torque" site="shoulder_pan_joint"/>
  <torque name="ur5e/joint2_torque" site="shoulder_lift_joint"/>
  <torque name="ur5e/joint3_torque" site="elbow_joint"/>
  <torque name="ur5e/joint4_torque" site="wrist_1_joint"/>
  <torque name="ur5e/joint5_torque" site="wrist_2_joint"/>
  <torque name="ur5e/joint6_torque" site="wrist_3_joint"/>

  <!-- Force sensor for the gripper -->
  <force name="ur5e/wrist_force" site="ur5e/attachment_site"/>

  <!-- Hand-E sensors (positions, quaternions, velocities) -->
  <framepos name="hande/pinch_pos" objtype="site" objname="pinch"/>
  <framequat name="hande/pinch_quat" objtype="site" objname="pinch"/>
  <framelinvel name="hande/pinch_vel" objtype="site" objname="pinch"/>
  </sensor>

</mujoco>
