<mujoco model="ur5e_with_hande">
  <compiler angle="radian"  autolimits="true"/>
  
  <option integrator="implicitfast"/>
  
  <!-- UR5e Robot Arm Definition -->
  <default>
    <default class="ur5e">
      <material specular="0.5" shininess="0.25"/>
      <joint axis="0 1 0" range="-6.28319 6.28319" armature="0.1"/>
      <general gaintype="fixed" biastype="affine" ctrlrange="-6.2831 6.2831" gainprm="2000" biasprm="0 -2000 -400"
        forcerange="-150 150"/>
      <default class="size3">
        <default class="size3_limited">
          <joint range="-3.1415 3.1415"/>
          <general ctrlrange="-3.1415 3.1415"/>
        </default>
      </default>
      <default class="size1">
        <general gainprm="500" biasprm="0 -500 -100" forcerange="-28 28"/>
      </default>
      <default class="visual">
        <geom type="mesh" contype="0" conaffinity="0" group="2"/>
      </default>
      <default class="collision">
        <geom type="capsule" group="3"/>
        <default class="eef_collision">
          <geom type="cylinder"/>
        </default>
      </default>
      <site size="0.001" rgba="0.5 0.5 0.5 0.3" group="4"/>
    </default>
  </default>

  <!-- Hand-E Gripper Definition -->
  <default>
    <default class="hande">
      <default class="hande_right_finger">
        <joint type="slide" range="0 0.025"/>
      </default>
      <default class="hande_left_finger">
        <joint type="slide" range="0 0.025"/>
      </default>
    </default>
  </default>

  <asset>
    <!-- UR5e Meshes -->
    <material class="ur5e" name="black" rgba="0.033 0.033 0.033 1"/>
    <material class="ur5e" name="jointgray" rgba="0.278 0.278 0.278 1"/>
    <material class="ur5e" name="linkgray" rgba="0.82 0.82 0.82 1"/>
    <material class="ur5e" name="urblue" rgba="0.49 0.678 0.8 1"/>
    
    <mesh file="ur5e/assets/base_0.obj"/>
    <mesh file="ur5e/assets/base_1.obj"/>
    <mesh file="ur5e/assets/shoulder_0.obj"/>
    <mesh file="ur5e/assets/upperarm_0.obj"/>
    <mesh file="ur5e/assets/forearm_0.obj"/>
    <mesh file="ur5e/assets/wrist1_0.obj"/>
    <mesh file="ur5e/assets/wrist2_0.obj"/>
    <mesh file="ur5e/assets/wrist3.obj"/>

    <!-- Hand-E Meshes -->
    <mesh name="hande" file="hande/assets/hande.stl"/>
    <mesh name="coupler" file="hande/assets/coupler.stl"/>
    <mesh name="right_finger" file="hande/assets/finger_1.stl"/>
    <mesh name="left_finger" file="hande/assets/finger_2.stl"/>
  </asset>

  <!-- UR5e Robot Arm Worldbody -->
  <worldbody>
    <light name="spotlight" mode="targetbodycom" target="wrist_2_link" pos="0 -1 2"/>
    <body name="base" quat="1 0 0 1" childclass="ur5e">
      <inertial mass="4.0" pos="0 0 0" diaginertia="0.00443333156 0.00443333156 0.0072"/>
      <geom mesh="base_0" material="black" class="visual"/>
      <geom mesh="base_1" material="jointgray" class="visual"/>
      
      <body name="shoulder_link" pos="0 0 0.163">
        <inertial mass="3.7" pos="0 0 0" diaginertia="0.0102675 0.0102675 0.00666"/>
        <joint name="shoulder_pan_joint" class="size3" axis="0 0 1"/>
        <geom mesh="shoulder_0" material="urblue" class="visual"/>
        
        <body name="upper_arm_link" pos="0 0.138 0" quat="1 0 1 0">
          <joint name="shoulder_lift_joint" class="size3"/>
          <geom mesh="upperarm_0" material="linkgray" class="visual"/>
          
          <body name="forearm_link" pos="0 -0.131 0.425">
            <joint name="elbow_joint" class="size3_limited"/>
            <geom mesh="forearm_0" material="urblue" class="visual"/>
            
            <body name="wrist_1_link" pos="0 0 0.392" quat="1 0 1 0">
              <joint name="wrist_1_joint" class="size1"/>
              <geom mesh="wrist1_0" material="black" class="visual"/>
              
              <body name="wrist_2_link" pos="0 0.127 0">
                <joint name="wrist_2_joint" axis="0 0 1" class="size1"/>
                <geom mesh="wrist2_0" material="black" class="visual"/>
                
                <body name="wrist_3_link" pos="0 0 0.1">
                  <joint name="wrist_3_joint" class="size1"/>
                  <geom mesh="wrist3" material="linkgray" class="visual"/>
                  
                  <!-- Hand-E Gripper Attached to Wrist -->
                  <body name="hande" pos="0 0 0.1">
                    <geom name="hande_coupler" type="mesh" conaffinity="0" group="1" rgba="0.1 0.1 0.1 1" mesh="coupler"/>
                    <geom name="hande_base" type="mesh" conaffinity="0" group="1" rgba="0.1 0.1 0.1 1" mesh="hande"/>
                    
                    <body name="hande_left_finger" pos="0 0 0.099">
                      <joint name="hande_left_finger_joint" class="hande_left_finger" pos="0 0 0" axis="1 0 0"/>
                      <geom type="mesh" contype="0" conaffinity="0" group="1" rgba="0.4 0.4 0.4 1" mesh="left_finger"/>
                    </body>
                    
                    <body name="hande_right_finger" pos="0 0 0.099">
                      <joint name="hande_right_finger_joint" class="hande_right_finger" pos="0 0 0" axis="-1 0 0"/>
                      <geom type="mesh" contype="0" conaffinity="0" group="1" rgba="0.4 0.4 0.4 1" mesh="right_finger"/>
                    </body>
                  </body>
                </body>
              </body>
            </body>
          </body>
        </body>
      </body>
    </body>
  </worldbody>

  <contact>
    <exclude body1="hande" body2="hande_left_finger" />
    <exclude body1="hande" body2="hande_right_finger" />
  </contact>
  <equality>
    <joint joint1="hande_left_finger_joint" joint2="hande_right_finger_joint" polycoef="0 1 0 0 0" />
  </equality>
  <tendon>
    <fixed name="split">
      <joint joint="hande_left_finger_joint" coef="0.5" />
      <joint joint="hande_right_finger_joint" coef="0.5" />
    </fixed>
  </tendon>

  <!-- Actuators -->
  <actuator>
    <general class="size3" name="shoulder_pan" joint="shoulder_pan_joint"/>
    <general class="size3" name="shoulder_lift" joint="shoulder_lift_joint"/>
    <general class="size3_limited" name="elbow" joint="elbow_joint"/>
    <general class="size1" name="wrist_1" joint="wrist_1_joint"/>
    <general class="size1" name="wrist_2" joint="wrist_2_joint"/>
    <general class="size1" name="wrist_3" joint="wrist_3_joint"/>

    <!-- Hand-E Actuator -->
    <general name="hande_fingers_actuator" class="hande" tendon="split" ctrlrange="0 255"
      forcerange="-180 180" gaintype="affine" biastype="affine" gainprm="0.00980392"
      biasprm="0 -100 -10"/>
  </actuator>

  <sensor>
  <!-- Joint positions for UR5e -->
  <jointpos name="ur5e/joint1_pos" joint="shoulder_pan_joint"/>
  <jointpos name="ur5e/joint2_pos" joint="shoulder_lift_joint"/>
  <jointpos name="ur5e/joint3_pos" joint="elbow_joint"/>
  <jointpos name="ur5e/joint4_pos" joint="wrist_1_joint"/>
  <jointpos name="ur5e/joint5_pos" joint="wrist_2_joint"/>
  <jointpos name="ur5e/joint6_pos" joint="wrist_3_joint"/>

  <!-- Joint velocities for UR5e -->
  <jointvel name="ur5e/joint1_vel" joint="shoulder_pan_joint"/>
  <jointvel name="ur5e/joint2_vel" joint="shoulder_lift_joint"/>
  <jointvel name="ur5e/joint3_vel" joint="elbow_joint"/>
  <jointvel name="ur5e/joint4_vel" joint="wrist_1_joint"/>
  <jointvel name="ur5e/joint5_vel" joint="wrist_2_joint"/>
  <jointvel name="ur5e/joint6_vel" joint="wrist_3_joint"/>

  <!-- Torque sensors for UR5e joints -->
  <torque name="ur5e/joint1_torque" site="shoulder_pan_joint"/>
  <torque name="ur5e/joint2_torque" site="shoulder_lift_joint"/>
  <torque name="ur5e/joint3_torque" site="elbow_joint"/>
  <torque name="ur5e/joint4_torque" site="wrist_1_joint"/>
  <torque name="ur5e/joint5_torque" site="wrist_2_joint"/>
  <torque name="ur5e/joint6_torque" site="wrist_3_joint"/>

  <!-- Force sensor for the gripper -->
  <force name="ur5e/wrist_force" site="attachment_site"/>

  <!-- Hand-E sensors (positions, quaternions, velocities) -->
  <framepos name="hande/tcp_pos" objtype="site" objname="tcp"/>
  <framequat name="hande/tcp_quat" objtype="site" objname="tcp"/>
  <framelinvel name="hande/tcp_vel" objtype="site" objname="tcp"/>
  </sensor>


  <keyframe>
    <key name="home" qpos="-1.5708 -1.5708 1.5708 -1.5708 -1.5708 0" ctrl="-1.5708 -1.5708 1.5708 -1.5708 -1.5708 0"/>
  </keyframe>
</mujoco>
