<?xml version="1.0"?>
<robot xmlns:xacro="http://ros.org/wiki/xacro">

  <xacro:include
    filename="$(find robotiq_hande_description)/urdf/inc/robotiq_hande.transmissions.xacro" />
  <xacro:include
    filename="$(find robotiq_hande_description)/urdf/inc/robotiq_hande_gazebo.xacro" />

  <xacro:macro name="robotiq_hande"
    params="
    prefix transmission_hw_interface:=hardware/interface/EffortJointInterface parent *origin add_cable_protector:=true">
    <!-- Add URDF transmission elements (for ros_control) -->
    <xacro:robotiq_hande_transmission prefix="${prefix}"
      hw_interface="${transmission_hw_interface}" />
    <xacro:robotiq_hande_gazebo prefix="${prefix}" />

    <xacro:property name="max_effort" value="130.0" />
    <xacro:property name="max_velocity" value="2.0" />


    <link name="${prefix}hande_left_finger">
      <inertial>
        <origin rpy="0 0 0" xyz="0.02262 -0.00759 0.00738"/>
        <mass value="0.03804"/>
        <inertia ixx="13567E-9" ixy="1849E-9" ixz="3622E-9" iyy="15784E-9" iyz="3616E-9" izz="7478E-9"/>
      </inertial>
      <visual>
        <origin rpy="0 0 0" xyz="0 0 0"/>
        <geometry>
          <mesh filename="package://robotiq_hande_description/meshes/hande/finger_1.dae" scale="1.0 1.0 1.0"/>
        </geometry>
        <material name="DarkGray">
          <color rgba=".4 0.4 0.4 1.0"/>
        </material>
      </visual>
      <collision>
        <origin rpy="0 0 0" xyz="0 0 0"/>
        <geometry>
          <mesh filename="package://robotiq_hande_description/meshes/hande/finger_1-collision.dae" scale="1.0 1.0 1.0"/>
        </geometry>
      </collision>
    </link>
    <link name="${prefix}hande_right_finger">
      <inertial>
        <origin rpy="0 0 0" xyz="-0.02262 0.00759 0.00738"/>
        <mass value="0.03804"/>
        <inertia ixx="13567E-9" ixy="1849E-9" ixz="-3622E-9" iyy="15784E-9" iyz="-3616E-9" izz="7478E-9"/>
      </inertial>
      <visual>
        <origin rpy="0 0 0" xyz="0 0 0"/>
        <geometry>
          <mesh filename="package://robotiq_hande_description/meshes/hande/finger_2.dae" scale="1.0 1.0 1.0"/>
        </geometry>
        <material name="DarkGray">
          <color rgba=".4 0.4 0.4 1.0"/>
        </material>
      </visual>
      <collision>
        <origin rpy="0 0 0" xyz="0 0 0"/>
        <geometry>
          <mesh filename="package://robotiq_hande_description/meshes/hande/finger_2-collision.dae" scale="1.0 1.0 1.0"/>
        </geometry>
      </collision>
    </link>

    <joint name="${prefix}hande_left_finger_joint" type="prismatic">
      <origin rpy="0 0 0" xyz="0 0 0.099"/>
      <parent link="${prefix}gripper_body"/>
      <child link="${prefix}hande_left_finger"/>
      <axis xyz="-1 0 0"/>
      <limit effort="130" lower="0" upper="0.025" velocity="0.15"/>
    </joint>
    <joint name="${prefix}hande_right_finger_joint" type="prismatic">
      <origin rpy="0 0 0" xyz="0 0 0.099"/>
      <parent link="${prefix}gripper_body"/>
      <child link="${prefix}hande_right_finger"/>
      <axis xyz="1 0 0"/>
      <limit effort="130" lower="0" upper="0.025" velocity="0.15"/>
      <mimic joint="${prefix}hande_left_finger_joint" multiplier="1" offset="0"/>
    </joint>

    <!-- base link -->

    <link name="${prefix}coupler">
      <inertial>
        <origin xyz="-0.0016434089410331007 -0.0004181643687079058 ${-0.005581211139100582+0.011}"
          rpy="0 0 0" />
        <mass value="${0.2723365896184866*0.37150924577}" />
        <inertia ixx="${0.000118*0.37150924577}" iyy="${0.000124*0.37150924577}"
          izz="${0.000233*0.37150924577}" ixy="${1e-06*0.37150924577}" iyz="${1e-06*0.37150924577}"
          ixz="${0.0*0.37150924577}" />
      </inertial>
      <visual>
        <origin xyz="0 0 0.011" rpy="0 0 0" />
        <geometry>
          <mesh
            filename="package://robotiq_2f_85_gripper_description/meshes/visual/robotiq_arg2f_85_coupler.stl"
            scale="0.001 0.001 0.001" />
        </geometry>
        <material name="">
          <color rgba="0.1 0.1 0.1 1" />
        </material>
      </visual>
      <collision>
        <origin xyz="0 0 0.011" rpy="0 0 0" />
        <geometry>
          <mesh
            filename="package://robotiq_2f_85_gripper_description/meshes/collision/robotiq_arg2f_85_coupler.stl"
            scale="0.001 0.001 0.001" />
        </geometry>
      </collision>
    </link>
    <joint name="${prefix}coupler_joint" type="fixed">
      <parent link="${parent}" />
      <child link="${prefix}coupler" />
      <xacro:insert_block name="origin" />
    </joint>

    <xacro:if value="${add_cable_protector}">
      <link name="${prefix}cable_protector">
        <inertial>
          <origin xyz="0.010499078826396276 0.011473161325063826 -0.026205571104648606" rpy="0 0 0" />
          <mass value="0.013386670447320692" />
          <inertia ixx="6e-06" iyy="7e-06" izz="2e-06" ixy="0.0" iyz="0.0" ixz="0.0" />
        </inertial>
        <visual>
          <origin xyz="0.0105 -0.034 0.008" rpy="0 0 0" />
          <geometry>
            <mesh
              filename="package://robotiq_2f_85_gripper_description/meshes/visual/robotiq_arg2f_85_cable_protector.stl"
              scale="0.001 0.001 0.001" />
          </geometry>
          <material name="">
            <color rgba="0.1 0.1 0.1 1" />
          </material>
        </visual>
        <collision>
          <origin xyz="0.0105 -0.034 0.008" rpy="0 0 0" />
          <geometry>
            <mesh
              filename="package://robotiq_2f_85_gripper_description/meshes/collision/robotiq_arg2f_85_cable_protector.stl"
              scale="0.001 0.001 0.001" />
          </geometry>
        </collision>
      </link>
      <joint name="${prefix}cable_protector_joint" type="fixed">
        <origin xyz="-0.0105 0.034 ${0.011-0.008}" rpy="0 0 0" />
        <parent link="${prefix}coupler" />
        <child link="${prefix}cable_protector" />
      </joint>
    </xacro:if>


    <joint name="${prefix}gripper_body_joint" type="fixed">
      <origin xyz="0 0 0.011" rpy="0 0 ${-pi/2}" />
      <parent link="${prefix}coupler" />
      <child link="${prefix}gripper_body" />
    </joint>
  
    <link name="${prefix}gripper_body">
      <inertial>
        <origin rpy="0 0 0" xyz="0 0 0.04607"/>
        <mass value="0.86387"/>
        <inertia ixx="1017560E-9" ixy="0" ixz="2235E-9" iyy="1028041E-9" iyz="0" izz="489810E-9"/>
      </inertial>
      <visual>
        <origin rpy="0 0 0" xyz="0 0 0"/>
        <geometry>
          <mesh filename="package://robotiq_hande_description/meshes/hande/hand-e.dae" scale="1.0 1.0 1.0"/>
        </geometry>
        <material name="Dark">
          <color rgba=".1 0.1 0.1 1.0"/>
        </material>
      </visual>
      <collision>
        <origin rpy="0 0 0" xyz="0 0 0"/>
        <geometry>
          <mesh filename="package://robotiq_hande_description/meshes/hande/hand-e-collision.dae" scale="1.0 1.0 1.0"/>
        </geometry>
      </collision>
    </link>


  </xacro:macro>
</robot>